[2022-09-10T06:24:12.358+0000] {taskinstance.py:1171} INFO - Dependencies all met for <TaskInstance: python_operator_v2.greet manual__2022-09-10T06:19:09.886887+00:00 [queued]>
[2022-09-10T06:24:12.371+0000] {taskinstance.py:1171} INFO - Dependencies all met for <TaskInstance: python_operator_v2.greet manual__2022-09-10T06:19:09.886887+00:00 [queued]>
[2022-09-10T06:24:12.372+0000] {taskinstance.py:1368} INFO - 
--------------------------------------------------------------------------------
[2022-09-10T06:24:12.372+0000] {taskinstance.py:1369} INFO - Starting attempt 2 of 6
[2022-09-10T06:24:12.372+0000] {taskinstance.py:1370} INFO - 
--------------------------------------------------------------------------------
[2022-09-10T06:24:12.551+0000] {taskinstance.py:1389} INFO - Executing <Task(PythonOperator): greet> on 2022-09-10 06:19:09.886887+00:00
[2022-09-10T06:24:12.556+0000] {standard_task_runner.py:52} INFO - Started process 722 to run task
[2022-09-10T06:24:12.558+0000] {standard_task_runner.py:79} INFO - Running: ['***', 'tasks', 'run', 'python_operator_v2', 'greet', 'manual__2022-09-10T06:19:09.886887+00:00', '--job-id', '18', '--raw', '--subdir', 'DAGS_FOLDER/dag_with_postgres_operator.py', '--cfg-path', '/tmp/tmpumz9m9tp', '--error-file', '/tmp/tmpl1410a0i']
[2022-09-10T06:24:12.559+0000] {standard_task_runner.py:80} INFO - Job 18: Subtask greet
[2022-09-10T06:24:12.631+0000] {task_command.py:371} INFO - Running <TaskInstance: python_operator_v2.greet manual__2022-09-10T06:19:09.886887+00:00 [running]> on host 55836be23227
[2022-09-10T06:24:12.721+0000] {taskinstance.py:1583} INFO - Exporting the following env vars:
AIRFLOW_CTX_DAG_OWNER=clickSpikes
AIRFLOW_CTX_DAG_ID=python_operator_v2
AIRFLOW_CTX_TASK_ID=greet
AIRFLOW_CTX_EXECUTION_DATE=2022-09-10T06:19:09.886887+00:00
AIRFLOW_CTX_TRY_NUMBER=2
AIRFLOW_CTX_DAG_RUN_ID=manual__2022-09-10T06:19:09.886887+00:00
[2022-09-10T06:24:12.729+0000] {taskinstance.py:1902} ERROR - Task failed with exception
Traceback (most recent call last):
  File "/home/airflow/.local/lib/python3.7/site-packages/selenium/webdriver/common/service.py", line 76, in start
    creationflags=self.creationflags)
  File "/usr/local/lib/python3.7/subprocess.py", line 800, in __init__
    restore_signals, start_new_session)
  File "/usr/local/lib/python3.7/subprocess.py", line 1551, in _execute_child
    raise child_exception_type(errno_num, err_msg, err_filename)
FileNotFoundError: [Errno 2] No such file or directory: '/home/airflow/chromedriver/stable/chromedriver': '/home/airflow/chromedriver/stable/chromedriver'

During handling of the above exception, another exception occurred:

Traceback (most recent call last):
  File "/home/airflow/.local/lib/python3.7/site-packages/airflow/operators/python.py", line 171, in execute
    return_value = self.execute_callable()
  File "/home/airflow/.local/lib/python3.7/site-packages/airflow/operators/python.py", line 189, in execute_callable
    return self.python_callable(*self.op_args, **self.op_kwargs)
  File "/opt/airflow/dags/dag_with_postgres_operator.py", line 28, in greet
    browser = webdriver.Chrome(service=webdriver_service, options=chrome_options)
  File "/home/airflow/.local/lib/python3.7/site-packages/selenium/webdriver/chrome/webdriver.py", line 72, in __init__
    service_log_path, service, keep_alive)
  File "/home/airflow/.local/lib/python3.7/site-packages/selenium/webdriver/chromium/webdriver.py", line 89, in __init__
    self.service.start()
  File "/home/airflow/.local/lib/python3.7/site-packages/selenium/webdriver/common/service.py", line 83, in start
    os.path.basename(self.path), self.start_error_message)
selenium.common.exceptions.WebDriverException: Message: 'chromedriver' executable needs to be in PATH. Please see https://chromedriver.chromium.org/home

[2022-09-10T06:24:12.740+0000] {taskinstance.py:1412} INFO - Marking task as UP_FOR_RETRY. dag_id=python_operator_v2, task_id=greet, execution_date=20220910T061909, start_date=20220910T062412, end_date=20220910T062412
[2022-09-10T06:24:12.760+0000] {standard_task_runner.py:97} ERROR - Failed to execute job 18 for task greet (Message: 'chromedriver' executable needs to be in PATH. Please see https://chromedriver.chromium.org/home
; 722)
[2022-09-10T06:24:12.771+0000] {local_task_job.py:156} INFO - Task exited with return code 1
[2022-09-10T06:24:12.803+0000] {local_task_job.py:279} INFO - 0 downstream tasks scheduled from follow-on schedule check
